Workbook

Sheet OSCAR PINEDA
A1: CONDUCTOR | B1: OSCAR PINEDA | E1: CIUDAD | F1: BOGOTÁ
A2: FECHA | B2: REMISIÓN | C2: PESO klg | D2: PESO TN | E2: PRECIO | F2: VAL/TOTAL | G2: ACTIVIDAD
G3: F.Bogota
B4: FT 571 | C4: 465.2 | D4: =+C4/1000 -> 0.4652 | E4: =IF(G4=1,4500,2500) -> 2500 | F4: =E4*D4 -> 1163
B5: 31940 | C5: 2726.9208 | D5: =C5/1000 -> 2.7269208 | E5: =IF(G5=1,4500,2500) -> 2500 | F5: =E5*D5 -> 6817.3021
B6: 31939 | C6: 4560.11 | D6: =+C6/1000 -> 4.56011 | E6: =IF(G6=1,4500,2500) -> 2500 | F6: =E6*D6 -> 11400.275
B7: 31935 | C7: 65.733333 | D7: =+C7/1000 -> 0.065733333 | E7: =IF(G7=1,4500,2500) -> 4500 | F7: =E7*D7 -> 295.8 | G7: 1
B8: FT 561 | C8: 7200 | D8: =+C8/1000 -> 7.2 | E8: =IF(G8=1,4500,2500) -> 2500 | F8: =E8*D8 -> 18000
B9: FT 569 | C9: 856 | D9: =+C9/1000 -> 0.856 | E9: =IF(G9=1,4500,2500) -> 4500 | F9: =E9*D9 -> 3852 | G9: 1
B10: FM 1053 | C10: 391.86667 | D10: =+C10/1000 -> 0.39186667 | E10: =IF(G10=1,4500,2500) -> 4500 | F10: =E10*D10 -> 1763.4 | G10: 1
B11: 31955 | C11: 507.28 | D11: =+C11/1000 -> 0.50728 | E11: =IF(G11=1,4500,2500) -> 2500 | F11: =E11*D11 -> 1268.2
B12: FM 1073 | C12: 4115.65 | D12: =+C12/1000 -> 4.11565 | E12: =IF(G12=1,4500,2500) -> 2500 | F12: =E12*D12 -> 10289.125
B13: FT 579 | C13: 1280 | D13: =+C13/1000 -> 1.28 | E13: =IF(G13=1,4500,2500) -> 2500 | F13: =E13*D13 -> 3200
B14: FM 1062 | C14: 5525 | D14: =+C14/1000 -> 5.525 | E14: =IF(G14=1,4500,2500) -> 2500 | F14: =E14*D14 -> 13812.5
B15: FT 583 | C15: 320 | D15: =+C15/1000 -> 0.32 | E15: =IF(G15=1,4500,2500) -> 2500 | F15: =E15*D15 -> 800
B16: 31958 | C16: 3917.1 | D16: =+C16/1000 -> 3.9171 | E16: =IF(G16=1,4500,2500) -> 2500 | F16: =E16*D16 -> 9792.75
D17: =+C17/1000 -> 0 | E17: =IF(G17=1,4500,2500) -> 2500 | F17: =E17*D17 -> 0
D18: =+C18/1000 -> 0 | E18: =IF(G18=1,4500,2500) -> 2500 | F18: =E18*D18 -> 0
D19: =+C19/1000 -> 0 | E19: =IF(G19=1,4500,2500) -> 2500 | F19: =E19*D19 -> 0
D20: =+C20/1000 -> 0 | E20: =IF(G20=1,4500,2500) -> 2500 | F20: =E20*D20 -> 0
D21: =+C21/1000 -> 0 | E21: =IF(G21=1,4500,2500) -> 2500 | F21: =E21*D21 -> 0
D22: =+C22/1000 -> 0 | E22: =IF(G22=1,4500,2500) -> 2500 | F22: =E22*D22 -> 0
D23: =+C23/1000 -> 0 | E23: =IF(G23=1,4500,2500) -> 2500 | F23: =E23*D23 -> 0
D24: =+C24/1000 -> 0 | E24: =IF(G24=1,4500,2500) -> 2500 | F24: =E24*D24 -> 0
D25: =+C25/1000 -> 0 | E25: =IF(G25=1,4500,2500) -> 2500 | F25: =E25*D25 -> 0
D26: =+C26/1000 -> 0 | E26: =IF(G26=1,4500,2500) -> 2500 | F26: =E26*D26 -> 0
D27: =+C27/1000 -> 0 | E27: =IF(G27=1,4500,2500) -> 2500 | F27: =E27*D27 -> 0
D28: =+C28/1000 -> 0 | E28: =IF(G28=1,4500,2500) -> 2500 | F28: =E28*D28 -> 0
... D31: =+C31/1000 -> 0 | E31: =IF(G31=1,4500,2500) -> 2500 | F31: =E31*D31 -> 0
C32: T.TON | D32: =SUM(D4:D13) -> 22.168761 | E32: TOTAL | F32: =SUM(F4:F31) -> 82454.352

Sheet MARIO MARTINEZ
A1: CONDUCTOR | B1: MARIO MARTINEZ | E1: CIUDAD | F1: BOGOTÁ
A2: FECHA | B2: REMISIÓN | C2: PESO klg | D2: PESO TN | E2: PRECIO | F2: VAL/TOTAL | G2: ACTIVIDAD
G3: F.Bogota
B4: FM 1058 | C4: 627.78 | D4: =+C4/1000 -> 0.62778 | E4: =IF(G4=1,4500,2500) -> 2500 | F4: =E4*D4 -> 1569.45
B5: 31945 | C5: 155 | D5: =+C5/1000 -> 0.155 | E5: =IF(G5=1,4500,2500) -> 2500 | F5: =E5*D5 -> 387.5
B6: FM 1052 | C6: 5626.7086 | D6: =+C6/1000 -> 5.6267086 | E6: =IF(G6=1,4500,2500) -> 4500 | F6: =E6*D6 -> 25320.189 | G6: 1
B7: FT 568 | C7: 384 | D7: =+C7/1000 -> 0.384 | E7: =IF(G7=1,4500,2500) -> 4500 | F7: =E7*D7 -> 1728 | G7: 1
B8: FM 1055 | C8: 3280 | D8: =+C8/1000 -> 3.28 | E8: =IF(G8=1,4500,2500) -> 2500 | F8: =E8*D8 -> 8200
B9: 31953 | C9: 805.86 | D9: =+C9/1000 -> 0.80586 | E9: =IF(G9=1,4500,2500) -> 2500 | F9: =E9*D9 -> 2014.65
B10: 8544 | C10: 110.73333 | D10: =+C10/1000 -> 0.11073333 | E10: =IF(G10=1,4500,2500) -> 4500 | F10: =E10*D10 -> 498.3 | G10: 1
B11: FM 1052 | C11: 5626.7086 | D11: =+C11/1000 -> 5.6267086 | E11: =IF(G11=1,4500,2500) -> 4500 | F11: =E11*D11 -> 25320.189 | G11: 1
B12: 31949 | C12: 2476.0833 | D12: =+C12/1000 -> 2.4760833 | E12: =IF(G12=1,4500,2500) -> 2500 | F12: =E12*D12 -> 6190.2083
B13: FT 574 | C13: 900 | D13: =+C13/1000 -> 0.9 | E13: =IF(G13=1,4500,2500) -> 2500 | F13: =E13*D13 -> 2250
B14: 31957 | C14: 952 | D14: =+C14/1000 -> 0.952 | E14: =IF(G14=1,4500,2500) -> 2500 | F14: =E14*D14 -> 2380
B15: FT 581 | C15: 1930 | D15: =+C15/1000 -> 1.93 | E15: =IF(G15=1,4500,2500) -> 2500 | F15: =E15*D15 -> 4825
B16: FT 580 | C16: 48 | D16: =+C16/1000 -> 0.048 | E16: =IF(G16=1,4500,2500) -> 2500 | F16: =E16*D16 -> 120
B17: FM 1072 | C17: 1818.8 | D17: =+C17/1000 -> 1.8188 | E17: =IF(G17=1,4500,2500) -> 2500 | F17: =E17*D17 -> 4547
D18: =C18/1000 -> 0 | E18: =IF(G18=1,4500,2500) -> 2500 | F18: =E18*D18 -> 0
D19: =C19/1000 -> 0 | E19: =IF(G19=1,4500,2500) -> 2500 | F19: =E19*D19 -> 0
D20: =C20/1000 -> 0 | E20: =IF(G20=1,4500,2500) -> 2500 | F20: =E20*D20 -> 0
D21: =C21/1000 -> 0 | E21: =IF(G21=1,4500,2500) -> 2500 | F21: =E21*D21 -> 0
D22: =C22/1000 -> 0 | E22: =IF(G22=1,4500,2500) -> 2500 | F22: =E22*D22 -> 0
D23: =C23/1000 -> 0 | E23: =IF(G23=1,4500,2500) -> 2500 | F23: =E23*D23 -> 0
D24: =C24/1000 -> 0 | E24: =IF(G24=1,4500,2500) -> 2500 | F24: =E24*D24 -> 0
D25: =C25/1000 -> 0 | E25: =IF(G25=1,4500,2500) -> 2500 | F25: =E25*D25 -> 0
D26: =C26/1000 -> 0 | E26: =IF(G26=1,4500,2500) -> 2500 | F26: =E26*D26 -> 0
D27: =C27/1000 -> 0 | E27: =IF(G27=1,4500,2500) -> 2500 | F27: =E27*D27 -> 0
D28: =C28/1000 -> 0 | E28: =IF(G28=1,4500,2500) -> 2500 | F28: =E28*D28 -> 0
D29: =C29/1000 -> 0 | E29: =IF(G29=1,4500,2500) -> 2500 | F29: =E29*D29 -> 0
... D32: =C32/1000 -> 0 | E32: =IF(G32=1,4500,2500) -> 2500 | F32: =E32*D32 -> 0
C33: T.TON | D33: =+SUM(D4:D20) -> 24.741674 | E33: TOTAL | F33: =SUM(F4:F32) -> 85350.485

Sheet JOSE GUEVARA
A1: CONDUCTOR | B1: JOSE GUEVARA | E1: CIUDAD | F1: BOGOTÁ
A2: FECHA | B2: REMISIÓN | C2: PESO klg | D2: PESO TN | E2: PRECIO | F2: VAL/TOTAL | G2: ACTIVIDAD
G3: F.Bogota
B4: 31938 | C4: 3030.9838 | D4: =+C4/1000 -> 3.0309838 | E4: =IF(G4=1,4500,2500) -> 2500 | F4: =E4*D4 -> 7577.4596
B5: FM 1056 | C5: 6066.7432 | D5: =C5/1000 -> 6.0667432 | E5: =IF(G5=1,4500,2500) -> 2500 | F5: =E5*D5 -> 15166.858
B6: FM 1071 | C6: 8854.6667 | D6: =+C6/1000 -> 8.8546667 | E6: =IF(G6=1,4500,2500) -> 2500 | F6: =E6*D6 -> 22136.667
B7: FM 1068 | C7: 4732.72 | D7: =+C7/1000 -> 4.73272 | E7: =IF(G7=1,4500,2500) -> 2500 | F7: =E7*D7 -> 11831.8
B8: 31943 | C8: 601.52 | D8: =+C8/1000 -> 0.60152 | E8: =IF(G8=1,4500,2500) -> 2500 | F8: =E8*D8 -> 1503.8
B9: FM 1065 | C9: 514.08 | D9: =+C9/1000 -> 0.51408 | E9: =IF(G9=1,4500,2500) -> 2500 | F9: =E9*D9 -> 1285.2
B10: FM 1064 | C10: 1820.6 | D10: =+C10/1000 -> 1.8206 | E10: =IF(G10=1,4500,2500) -> 2500 | F10: =E10*D10 -> 4551.5
B11: FM 1079 | C11: 51.87 | D11: =+C11/1000 -> 0.05187 | E11: =IF(G11=1,4500,2500) -> 2500 | F11: =E11*D11 -> 129.675
B12: FM 520 | C12: 434.34 | D12: =+C12/1000 -> 0.43434 | E12: =IF(G12=1,4500,2500) -> 2500 | F12: =E12*D12 -> 1085.85
B13: FT 584 | C13: 960 | D13: =C13/1000 -> 0.96 | E13: =IF(G13=1,4500,2500) -> 2500 | F13: =E13*D13 -> 2400
B14: FM 1078 | C14: 1258.63 | D14: =C14/1000 -> 1.25863 | E14: =IF(G14=1,4500,2500) -> 2500 | F14: =E14*D14 -> 3146.575
D15: =C15/1000 -> 0 | E15: =IF(G15=1,4500,2500) -> 2500 | F15: =E15*D15 -> 0
D16: =C16/1000 -> 0 | E16: =IF(G16=1,4500,2500) -> 2500 | F16: =E16*D16 -> 0
D17: =C17/1000 -> 0 | E17: =IF(G17=1,4500,2500) -> 2500 | F17: =E17*D17 -> 0
D18: =C18/1000 -> 0 | E18: =IF(G18=1,4500,2500) -> 2500 | F18: =E18*D18 -> 0
D19: =C19/1000 -> 0 | E19: =IF(G19=1,4500,2500) -> 2500 | F19: =E19*D19 -> 0
D20: =C20/1000 -> 0 | E20: =IF(G20=1,4500,2500) -> 2500 | F20: =E20*D20 -> 0
D21: =C21/1000 -> 0 | E21: =IF(G21=1,4500,2500) -> 2500 | F21: =E21*D21 -> 0
D22: =C22/1000 -> 0 | E22: =IF(G22=1,4500,2500) -> 2500 | F22: =E22*D22 -> 0
D23: =C23/1000 -> 0 | E23: =IF(G23=1,4500,2500) -> 2500 | F23: =E23*D23 -> 0
D24: =C24/1000 -> 0 | E24: =IF(G24=1,4500,2500) -> 2500 | F24: =E24*D24 -> 0
D25: =C25/1000 -> 0 | E25: =IF(G25=1,4500,2500) -> 2500 | F25: =E25*D25 -> 0
D26: =C26/1000 -> 0 | E26: =IF(G26=1,4500,2500) -> 2500 | F26: =E26*D26 -> 0
... D31: =C31/1000 -> 0 | E31: =IF(G31=1,4500,2500) -> 2500 | F31: =E31*D31 -> 0
C32: T.TON | D32: =SUM(D4:D14) -> 28.326154 | E32: TOTAL | F32: =SUM(F4:F31) -> 70815.384

Sheet JIFFER NIETO
A1: CONDUCTOR | B1: JIFFER NIETO | E1: CIUDAD | F1: BOGOTÁ
A2: FECHA | B2: REMISIÓN | C2: PESO klg | D2: PESO TN | E2: PRECIO | F2: VAL/TOTAL | G2: ACTIVIDAD
G3: F.Bogota
B4: FT 573 | C4: 1152 | D4: =+C4/1000 -> 1.152 | E4: =IF(G4=1,4500,2500) -> 2500 | F4: =E4*D4 -> 2880
B5: 31941 | C5: 192 | D5: =+C5/1000 -> 0.192 | E5: =IF(G5=1,4500,2500) -> 2500 | F5: =E5*D5 -> 480
B6: FM 1051 | C6: 255.96 | D6: =+C6/1000 -> 0.25596 | E6: =IF(G6=1,4500,2500) -> 2500 | F6: =E6*D6 -> 639.9
B7: 31907 | C7: 1023.9 | D7: =+C7/1000 -> 1.0239 | E7: =IF(G7=1,4500,2500) -> 2500 | F7: =E7*D7 -> 2559.75
B8: FT 570 | C8: 147.2 | D8: =+C8/1000 -> 0.1472 | E8: =IF(G8=1,4500,2500) -> 2500 | F8: =E8*D8 -> 368
B9: FM 1054 | C9: 2796.0733 | D9: =+C9/1000 -> 2.7960733 | E9: =IF(G9=1,4500,2500) -> 2500 | F9: =E9*D9 -> 6990.1833
B10: FM 1063 | C10: 88.666667 | D10: =+C10/1000 -> 0.088666667 | E10: =IF(G10=1,4500,2500) -> 2500 | F10: =E10*D10 -> 221.66667
B11: 31926 | C11: 604.63 | D11: =+C11/1000 -> 0.60463 | E11: =IF(G11=1,4500,2500) -> 4500 | F11: =E11*D11 -> 2720.835 | G11: 1
B12: 31959 | C12: 3752.5 | D12: =+C12/1000 -> 3.7525 | E12: =IF(G12=1,4500,2500) -> 2500 | F12: =E12*D12 -> 9381.25
B13: FM 1077 | C13: 850.2 | D13: =+C13/1000 -> 0.8502 | E13: =IF(G13=1,4500,2500) -> 2500 | F13: =E13*D13 -> 2125.5
D14: =+C14/1000 -> 0 | E14: =IF(G14=1,4500,2500) -> 2500 | F14: =E14*D14 -> 0
D15: =+C15/1000 -> 0 | E15: =IF(G15=1,4500,2500) -> 2500 | F15: =E15*D15 -> 0
D16: =+C16/1000 -> 0 | E16: =IF(G16=1,4500,2500) -> 2500 | F16: =E16*D16 -> 0
D17: =+C17/1000 -> 0 | E17: =IF(G17=1,4500,2500) -> 2500 | F17: =E17*D17 -> 0
D18: =C18/1000 -> 0 | E18: =IF(G18=1,4500,2500) -> 2500 | F18: =E18*D18 -> 0
D19: =C19/1000 -> 0 | E19: =IF(G19=1,4500,2500) -> 2500 | F19: =E19*D19 -> 0
D20: =C20/1000 -> 0 | E20: =IF(G20=1,4500,2500) -> 2500 | F20: =E20*D20 -> 0
D21: =C21/1000 -> 0 | E21: =IF(G21=1,4500,2500) -> 2500 | F21: =E21*D21 -> 0
D22: =C22/1000 -> 0 | E22: =IF(G22=1,4500,2500) -> 2500 | F22: =E22*D22 -> 0
D23: =C23/1000 -> 0 | E23: =IF(G23=1,4500,2500) -> 2500 | F23: =E23*D23 -> 0
D24: =C24/1000 -> 0 | E24: =IF(G24=1,4500,2500) -> 2500 | F24: =E24*D24 -> 0
D25: =C25/1000 -> 0 | E25: =IF(G25=1,4500,2500) -> 2500 | F25: =E25*D25 -> 0
D26: =C26/1000 -> 0 | E26: =IF(G26=1,4500,2500) -> 2500 | F26: =E26*D26 -> 0
D27: =C27/1000 -> 0 | E27: =IF(G27=1,4500,2500) -> 2500 | F27: =E27*D27 -> 0
C28: T.TON | D28: =SUM(D4:D16) -> 10.86313 | E28: TOTAL | F28: =SUM(F4:F27) -> 28367.085

Sheet WILSON MARTINEZ
A1: CONDUCTOR | B1: WILSON MARTINEZ | E1: CIUDAD | F1: BOGOTÁ
A2: FECHA | B2: REMISIÓN | C2: PESO klg | D2: PESO TN | E2: PRECIO | F2: VAL/TOTAL | G2: ACTIVIDAD
G3: F.Bogota
B4: 31942 | C4: 0.9 | D4: =+C4/1000 -> 0.0009 | E4: =IF(G4=1,4500,2500) -> 2500 | F4: =E4*D4 -> 2.25
B5: 31944 | C5: 1245.2 | D5: =C5/1000 -> 1.2452 | E5: =IF(G5=1,4500,2500) -> 2500 | F5: =E5*D5 -> 3113
B6: FM 1057 | C6: 2536.9267 | D6: =+C6/1000 -> 2.5369267 | E6: =IF(G6=1,4500,2500) -> 2500 | F6: =E6*D6 -> 6342.3167
B7: FT 576 | C7: 5854 | D7: =C7/1000 -> 5.854 | E7: =IF(G7=1,4500,2500) -> 2500 | F7: =E7*D7 -> 14635
B8: 31928 | C8: 5391.9367 | D8: =+C8/1000 -> 5.3919367 | E8: =IF(G8=1,4500,2500) -> 2500 | F8: =E8*D8 -> 13479.842
B9: FM 1061 | C9: 9366.5 | D9: =C9/1000 -> 9.3665 | E9: =IF(G9=1,4500,2500) -> 2500 | F9: =E9*D9 -> 23416.25
B10: FM 518 | C10: 367.125 | D10: =+C10/1000 -> 0.367125 | E10: =IF(G10=1,4500,2500) -> 2500 | F10: =E10*D10 -> 917.8125
B11: FM 1066 | C11: 2630.7933 | D11: =C11/1000 -> 2.6307933 | E11: =IF(G11=1,4500,2500) -> 2500 | F11: =E11*D11 -> 6576.9833
B12: FT 578 | C12: 51.2 | D12: =+C12/1000 -> 0.0512 | E12: =IF(G12=1,4500,2500) -> 2500 | F12: =E12*D12 -> 128
B13: FT 577 | C13: 450 | D13: =C13/1000 -> 0.45 | E13: =IF(G13=1,4500,2500) -> 2500 | F13: =E13*D13 -> 1125
D14: =C14/1000 -> 0 | E14: =IF(G14=1,4500,2500) -> 2500 | F14: =E14*D14 -> 0
D15: =C15/1000 -> 0 | E15: =IF(G15=1,4500,2500) -> 2500 | F15: =E15*D15 -> 0
D16: =C16/1000 -> 0 | E16: =IF(G16=1,4500,2500) -> 2500 | F16: =E16*D16 -> 0
D17: =+C17/1000 -> 0 | E17: =IF(G17=1,4500,2500) -> 2500 | F17: =E17*D17 -> 0
D18: =C18/1000 -> 0 | E18: =IF(G18=1,4500,2500) -> 2500 | F18: =E18*D18 -> 0
D19: =C19/1000 -> 0 | E19: =IF(G19=1,4500,2500) -> 2500 | F19: =E19*D19 -> 0
D20: =C20/1000 -> 0 | E20: =IF(G20=1,4500,2500) -> 2500 | F20: =E20*D20 -> 0
D21: =C21/1000 -> 0 | E21: =IF(G21=1,4500,2500) -> 2500 | F21: =E21*D21 -> 0
D22: =C22/1000 -> 0 | E22: =IF(G22=1,4500,2500) -> 2500 | F22: =E22*D22 -> 0
D23: =C23/1000 -> 0 | E23: =IF(G23=1,4500,2500) -> 2500 | F23: =E23*D23 -> 0
D24: =C24/1000 -> 0 | E24: =IF(G24=1,4500,2500) -> 2500 | F24: =E24*D24 -> 0
D25: =C25/1000 -> 0 | E25: =IF(G25=1,4500,2500) -> 2500 | F25: =E25*D25 -> 0
D26: =C26/1000 -> 0 | E26: =IF(G26=1,4500,2500) -> 2500 | F26: =E26*D26 -> 0
D27: =C27/1000 -> 0 | E27: =IF(G27=1,4500,2500) -> 2500 | F27: =E27*D27 -> 0
C28: T.TON | D28: =SUM(D4:D16) -> 27.894582 | E28: TOTAL | F28: =SUM(F4:F27) -> 69736.454

Sheet PESO
A1: TONELAGE DE REMISION POR EQUIPOS ALFOREQUIPOS S.A.S
A2: EQUIPO | B2: UNIDAD | C2: PESO Klg | D2: TOTAL
A3: Abrazadera Fija | C3: 2 | D3: =B3*C3 -> 0
A4: Abrazadera Giratoria | C4: 2 | D4: =B4*C4 -> 0
A5: Alineador 0,70Mtr | C5: 5.0025 | D5: =B5*C5 -> 0
A6: Alineador 0,80Mtr | C6: 5.336 | D6: =B6*C6 -> 0
A7: Alineador 0,90Mtr | C7: 6.003 | D7: =B7*C7 -> 0
A8: Alineador 1,10Mtr | C8: 7.337 | D8: =B8*C8 -> 0
A9: Alineador 1,20Mtr | C9: 8.004 | D9: =B9*C9 -> 0
A10: Alineador 1,250Mtr | C10: 8.3375 | D10: =B10*C10 -> 0
A11: Alineador 1,30Mtr | C11: 8.671 | D11: =B11*C11 -> 0
A12: Alineador 1,35Mtr | C12: 9.0045 | D12: =B12*C12 -> 0
A13: Alineador 1,47Mtr | C13: 9.8049 | D13: =B13*C13 -> 0
A14: Alineador 1,4Mtr | C14: 9.338 | D14: =B14*C14 -> 0
... A22: Alineador 2,3Mtr | C22: 15.33525 | D22: =B22*C22 -> 0
A23: Alineador 2,45Mtr | C23: 16.33
A24: Alineador 2,4Mtr | C24: 16 | D24: =B24*C24 -> 0
A25: Alineador 2,5Mtr | C25: 16.666 | D25: =B25*C25 -> 0
A26: Alineador 2,6Mtr | C26: 17.34 | D26: =B26*C26 -> 0
A27: Alineador 2,7Mtr | C27: 18 | D27: =B27*C27 -> 0
A28: Alineador 2,80Mtr | C28: 18.6739 | D28: =B28*C28 -> 0
A29: Alineador 2,90Mtr | C29: 19.3408 | D29: =B29*C29 -> 0
A30: Alineador 2Mtr | C30: 13.333333 | D30: =B30*C30 -> 0
A31: Alineador 3,30Mtr | C31: 22.002 | D31: =B31*C31 -> 0
A32: Alineador 3,5Mtr | C32: 23.3355 | D32: =B32*C32 -> 0
A33: Alineador 3,75Mtr | C33: 25.0024 | D33: =B33*C33 -> 0
A34: Alineador 3,7Mtr | C34: 24.669 | D34: =B34*C34 -> 0
A35: Alineador 3Mtr | C35: 20 | D35: =B35*C35 -> 0
... A88: Cercha 3mt | C88: 24 | D88: =B88*C88 -> 0
A89: Compresor | D89: =B89*C89 -> 0
A90: Corbata 0,08Mtr | C90: 0.09 | D90: =B90*C90 -> 0
A91: Corbata 0,10Mtr | C91: 0.1125 | D91: =B91*C91 -> 0
A92: Corbata 0,15Mtr | C92: 0.16875 | D92: =B92*C92 -> 0
A93: Corbata 0,18Mtr | C93: 0.207 | D93: =B93*C93 -> 0
A94: Corbata 0,20Mtr | C94: 0.225 | D94: =B94*C94 -> 0
A95: Corbata 0,22mtr | C95: 0.253 | D95: =B95*C95 -> 0
A96: Corbata 0,24mtr | C96: 0.27 | D96: =B96*C96 -> 0
A97: Corbata 0,25mtr | C97: 0.28 | D97: =B97*C97 -> 0
A98: Corbata 0,27mtr | C98: 0.3037 | D98: =B98*C98 -> 0
A99: Corbata 0,30mtr | C99: 0.33 | D99: =B99*C99 -> 0
...

Sheet CONSOLIDADO
A1: CONDUCTOR | B1: TON | C1: TOTAL | D1: M.P C - N/C | E1: R.T.E C - N/C | F1: S.E Y R.E C - N/C | G1: C.L C - N/C | H1: P.P C - N/C
A2: OSCAR PINEDA | B2: ='OSCAR PINEDA'!D32 -> 22.168761 | C2: ='OSCAR PINEDA'!F32 -> 82454.352
A3: MARIO MARTINEZ | B3: ='MARIO MARTINEZ'!D33 -> 24.741674 | C3: ='MARIO MARTINEZ'!F33 -> 85350.485
A4: JOSE GUEVARA | B4: ='JOSE GUEVARA'!D32 -> 28.326154 | C4: ='JOSE GUEVARA'!F32 -> 70815.384
A5: JIFFER NIETO | B5: ='JIFFER NIETO'!D28 -> 10.86313 | C5: ='JIFFER NIETO'!F28 -> 28367.085
A6: WILSON MARTINEZ | B6: ='WILSON MARTINEZ'!D28 -> 27.894582 | C6: ='WILSON MARTINEZ'!F28 -> 69736.454
B7: TOTAL | C7: =+SUM(C2:C6) -> 336723.76
A9: OBSERVACIONES: - En esta ocasión, el corte es desde el 22/06/2026 hasta el 11/07/2026 - EL costo que se le asignó al tonelaje fue el siguiente: - Dentro de Bogota a $2.500°° (Dos mil pesos); Fuera de Bogota a $4.500°° (Cuatro mil pesos) El valor del costo por tonelada, por fuera y en la ciudad fue sumunistrado por el ING. Jhon Jairo Garcia. Este periodo de pago se tomará desde mayo
A11: PUNTOS A TENER EN CUENTA PARA ACCEDER AL PAGO POR TONELADAS CARGADAS
A12: 1. M.P - Realizar mantenimiento preventivo al carro: Quiere decir que el carro al salir debe estar en perfecto estado y no el mismo dia avisar del problema del carro, (El conductor debe velar por el buen estado de carro). (Avisar al mecanico o en su defecto a su jefe directo) 2. R.T.E - Recoger la totalidad del equipo: Indicarle al almacenista si se recogio la totalidad o si queda un parcial y es necesario que esto quede anotado en la remision 3. S.E Y R.E - Carro que sale debe llevar equipo para entregar, por ende debe regresar con equipo y con sus respectivas remisiones 3.1 C.L - Carro que sale con equipo, lo debe entregar el mismo dia. (De esto no suceder no se pagara esta remisión) 4. P.P - Buena presentacion personal: Tanto en la empresa como en las obras. 5. Los sábados se debe dejar los carros lavados, tanqueados y en su respectivo garaje o lugar de parqueo.

Sheet PESOS EQUI - ALFOR
A1: ELEMENTOS AMD | B1: PESO Kg Unidad
A2: VERTICAL CON ESPIGO 0,50mtr | B2: 2.5
A3: VERTICAL CON ESPIGO 1,00mtr | B3: 5
A4: VERTICAL CON ESPIGO 2,00mtr | B4: 10.5
A5: VERTICAL SIN ESPIGO 0,50mtr | B5: 2
A6: VERTICAL SIN ESPIGO 1,0mtr | B6: 4.5
A7: VERTICAL SIN ESPIGO 2,00mtr | B7: 10
A8: HORIZONTAL 0,70 mtr | B8: 2.9
A9: HORIZONTAL 1,40 mtr | B9: 4.7
A10: HORIZONTAL 2,00 mtr | B10: 5.8
A11: HORIZONTAL 3,00 mtr | B11: 9.5
A12: DIAGONAL 3,50 mtr | B12: 12.5
A13: DIAGONAL 2,40 mtr | B13: 9
... A48: PALOMERA | B48: 16
A49: COMPRESOR
A50: FORMACLAM | B50: 0.68
A51: Rinconera 0,15*0,15*1,20 | B51: 26
A52: Rinconera 0,15*0,15*0,60 | B52: 14
A53: Rinconera 0,10*0,10*1,20 | B53: 17.333333
A54: Tablero 0,600*1,20 | B54: 34
A55: Tablero 0,595*1,20 | B55: 33.716667
A56: Tablero 0,590*1,20 | B56: 33.433333
A57: Tablero 0,585*1,20 | B57: 33.15
A58: Tablero 0,580*1,20 | B58: 32.866667
A59: Tablero 0,575*1,20 | B59: 32.583333
A60: Tablero 0,570*1,20 | B60: 32.3
A61: Tablero 0,565*1,20 | B61: 32.016667
... A203: Saca-Módulos | B203: 3

Sheet PESO FT
A1: DESCRIPCION | B1: PESO Kg
A2: PARAL ENANO | B2: 7
A3: PARAL CORTO | B3: 12.5
A4: PARAL LARGO | B4: 17
A5: PARAL EXTRALARGO | B5: 22
A6: PARAL SUPER EXTRALARGO | B6: 24
A7: CERCHA | B7: 24
A8: CRUCETA CORTA | B8: 5
A9: CRUCETA LARGA | B9: 8
A10: CAMILLA DE MADERA | B10: 20
A11: ANDAMIO TUBULAR | B11: 15
A12: ESCALERA ANDAMIO | B12: 25
A13: CRUCETA DE ANDAMIO | B13: 8
... A17: PALOMERA | B17: 16
A18: COMPRESOR
A19: FORMCLAM | B19: 0.68

Sheet PESO FM
A1: ELEMENTOS FORMALETA METALICA | B1: CANTIDAD
A2: Rinconera 0,15*0,15*1,20 | B2: 26
A3: Rinconera 0,15*0,15*0,60 | B3: 14
A4: Rinconera 0,10*0,10*1,20 | B4: 17.333333
A5: Tablero 0,600*1,20 | B5: 34
A6: Tablero 0,595*1,20 | B6: 33.716667
A7: Tablero 0,590*1,20 | B7: 33.433333
A8: Tablero 0,585*1,20 | B8: 33.15
A9: Tablero 0,580*1,20 | B9: 32.866667
A10: Tablero 0,575*1,20 | B10: 32.583333
A11: Tablero 0,570*1,20 | B11: 32.3
A12: Tablero 0,565*1,20 | B12: 32.016667
A13: Tablero 0,560*1,20 | B13: 31.733333
... A115: Tablero 0,050*1,20 | B115: 2.8333333
A117: DESCRIPCION | B117: TOTAL PESO (Kg)
A118: Grapa o Chapeta | B118: 0.33
A119: Angulo | B119: 0.025
A120: Angulo | B120: 0.05
A121: Angulo | B121: 0.1
A122: Tensor o Mordaza | B122: 0.7
A123: Alineador | B123: 40
A124: Alineador | B124: 33.333333
A125: Alineador | B125: 26.666667
A126: Alineador | B126: 20
A127: Alineador | B127: 13.333333
A128: Alineador | B128: 6.6666667
A129: Pin | B129: 0.07
... A156: Saca-Módulos | B156: 3
